<!DOCTYPE html>
<html lang="en">
<head>
    <meta charset="UTF-8">
    <title>Title</title>
</head>
<body>

<!--错误是开发中不幸的副作用。这些操作符提供了一些高效的方式来优雅地处理错误并且在它们应该发生的情况下重试逻辑，-->
catch / catchError
函数签名: catchError(project : function): Observable
优雅地处理 observable 序列中的错误

<p>记住要在 catch 函数中返回一个 observable !</p>
</body>
<script src="https://unpkg.com/rxjs/bundles/rxjs.umd.min.js"></script>
<script type="text/javascript">
    // RxJS v6+
    const { throwError, of,timer, from } =rxjs;
    const { catchError,mergeMap } =rxjs.operators;

    /**案例1：捕获 observable 中的错误**/
    // 发出错误
    const source = throwError('This is an error!');
    // 优雅地处理错误，并返回带有错误信息的 observable
    const example = source.pipe(catchError(val => of(`I caught: ${val}`)));
    // 输出: 'I caught: This is an error'
    const subscribe = example.subscribe(val => console.log(val));

    /**案例2： 捕获拒绝的 promise**/
    // 创建立即拒绝的 Promise
    const myBadPromise = () =>
        new Promise((resolve, reject) => reject('Rejected!'));
    // 1秒后发出单个值
    const source2 = timer(1000);
    // 捕获拒绝的 promise，并返回包含错误信息的 observable
    const example2 = source2.pipe(
        mergeMap(_ =>
            from(myBadPromise()).pipe(catchError(error => of(`Bad Promise: ${error}`)))
        )
    );
    // 输出: 'Bad Promise: Rejected'
    const subscribe2 = example2.subscribe(val => console.log(val));

</script>
</html>
